Workbook

Sheet Contable
A1: Fecha | B1: Descripcion | C1: Tipo Movimiento | D1: Monto | E1: Categoria | F1: Cuenta Origen | G1: Cuenta Destino | H1: Mes | I1: Total
A2: 45934 | B2: Aplicacion Inicial Liquido | C2: Ingreso | D2: 6930000 | E2: Aplicacion | G2: Naranja X | H2: =TEXT(A2,"mmmm yyyy") -> octubre 2025
A3: 45936 | B3: Uber | C3: Ingreso | D3: 147000 | E3: Uber | G3: Naranja X | H3: =TEXT(A3,"mmmm yyyy") -> octubre 2025
A4: 45937 | B4: Gastos varios, adelanto celu, milas y corte de pelo | C4: Gasto | D4: 30000 | E4: Gastos | F4: Naranja X | H4: =TEXT(A4,"mmmm yyyy") -> octubre 2025
A5: 45938 | B5: Sueldo Septiembre | C5: Ingreso | D5: 2152000 | E5: Sueldo | G5: Naranja X | H5: =TEXT(A5,"mmmm yyyy") -> octubre 2025
A6: 45939 | B6: Transferencia Sergio | C6: Gasto | D6: 330000 | E6: Inversion | F6: Naranja X | H6: =TEXT(A6,"mmmm yyyy") -> octubre 2025
A7: 45939 | B7: Transferencia Raul Suares Septtiembre | C7: Gasto | D7: 220000 | E7: Inversion | F7: Naranja X | H7: =TEXT(A7,"mmmm yyyy") -> octubre 2025
A8: 45942 | B8: Pago Seguro Auto | C8: Gasto | D8: 20000 | E8: Servicios | F8: Naranja X | H8: =TEXT(A8,"mmmm yyyy") -> octubre 2025
A9: 45942 | B9: Pago Cuota Regalo 1/2 Pamela Saravia | C9: Gasto | D9: 30000 | E9: Gastos | F9: Naranja X | H9: =TEXT(A9,"mmmm yyyy") -> octubre 2025
A10: 45942 | B10: Gastos Finde | C10: Gasto | D10: 40000 | E10: Gastos | F10: Naranja X | H10: =TEXT(A10,"mmmm yyyy") -> octubre 2025
A11: 45943 | B11: Modulo Celular A02s | C11: Gasto | D11: 25000 | E11: Gastos | F11: Naranja X | H11: =TEXT(A11,"mmmm yyyy") -> octubre 2025
A12: 45943 | B12: Devolucion Cuota Bebe 2/3 | C12: Ingreso | D12: 82000 | E12: Prestamo | G12: Naranja X | H12: =TEXT(A12,"mmmm yyyy") -> octubre 2025
A13: 45943 | B13: Gastos Combustible | C13: Gasto | D13: 60000 | E13: Combustible | F13: Naranja X | H13: =TEXT(A13,"mmmm yyyy") -> octubre 2025
A14: 45952 | B14: Gastos Finde Semana | C14: Gasto | D14: 60000 | E14: Gastos | F14: Naranja X | H14: =TEXT(A14,"mmmm yyyy") -> octubre 2025
A15: 45952 | B15: Pago total de tarjeta Naranja X Cuotas | C15: Gasto | D15: 513000 | E15: Tarjeta | F15: Naranja X | H15: =TEXT(A15,"mmmm yyyy") -> octubre 2025
A16: 45952 | B16: Payo Transferencia Trabajo 4 dias | C16: Gasto | D16: 100000 | E16: Inversion | F16: Naranja X | H16: =TEXT(A16,"mmmm yyyy") -> octubre 2025
A17: 45952 | B17: Papa transferencia | C17: Gasto | D17: 87500 | E17: Inversion | F17: Naranja X | H17: =TEXT(A17,"mmmm yyyy") -> octubre 2025
A18: 45954 | B18: Mochila Para Fumigar | C18: Gasto | D18: 190000 | E18: Inversion | F18: Naranja X | H18: =TEXT(A18,"mmmm yyyy") -> octubre 2025
A19: 45954 | B19: Coadyudante Para fumigar | C19: Gasto | D19: 63000 | E19: Inversion | F19: Naranja X | H19: =TEXT(A19,"mmmm yyyy") -> octubre 2025
A20: 45955 | B20: Papa transferencia | C20: Gasto | D20: 400000 | E20: Prestamo | F20: Naranja X | H20: =TEXT(A20,"mmmm yyyy") -> octubre 2025
A21: 45955 | B21: Papa Efectivo Prestamo | C21: Gasto | D21: 400000 | E21: Prestamo | F21: Naranja X | H21: =TEXT(A21,"mmmm yyyy") -> octubre 2025
A22: 45955 | B22: Jose Octubre 5 dias | C22: Gasto | D22: 125000 | E22: Inversion | F22: Naranja X | H22: =TEXT(A22,"mmmm yyyy") -> octubre 2025
A23: 45957 | B23: Gastos Finde Semana | C23: Gasto | D23: 18000 | E23: Gastos | F23: Naranja X | H23: =TEXT(A23,"mmmm yyyy") -> octubre 2025
A24: 45958 | B24: Luz Octubre | C24: Gasto | D24: 132669 | E24: Servicios | F24: Naranja X | H24: =TEXT(A24,"mmmm yyyy") -> octubre 2025
... A33: 45966 | B33: Tarjeta Octubre | C33: Gasto | D33: 98000 | E33: Tarjeta | F33: Naranja X | H33: =TEXT(A33,"mmmm yyyy") -> noviembre 2025
A34: 45966 | B34: Rendimiento Frasco | C34: Ingreso | D34: 66480 | E34: Frasco | G34: Naranja X | H34: =TEXT(A34,"mmmm yyyy") -> noviembre 2025
A35: 45966 | B35: Raul Octubre 14 dias | C35: Gasto | D35: 350000 | E35: Inversion | F35: Naranja X | H35: =TEXT(A35,"mmmm yyyy") -> noviembre 2025
A36: 45968 | B36: Sueldo Octubre Santa Clara | C36: Ingreso | D36: 2070000 | E36: Sueldo | G36: Naranja X | H36: =TEXT(A36,"mmmm yyyy") -> noviembre 2025
A37: 45969 | B37: Uber Finde Efectivo | C37: Ingreso | D37: 24000 | E37: Uber | G37: Naranja X | H37: =TEXT(A37,"mmmm yyyy") -> noviembre 2025
A38: 45970 | B38: Uber Transferencia | C38: Ingreso | D38: 15000 | E38: Uber | G38: Naranja X | H38: =TEXT(A38,"mmmm yyyy") -> noviembre 2025
A39: 45971 | B39: Devolucion Marimar Prestamos | C39: Gasto | D39: 30000 | E39: Gastos | F39: Naranja X | H39: =TEXT(A39,"mmmm yyyy") -> noviembre 2025
A40: 45971 | B40: Sandwiches | C40: Gasto | D40: 13500 | E40: Gastos | F40: Naranja X | H40: =TEXT(A40,"mmmm yyyy") -> noviembre 2025
A41: 45971 | B41: Pago Cuota Regalo 2/2 Pamela Saravia | C41: Gasto | D41: 29500 | E41: Gastos | F41: Naranja X | H41: =TEXT(A41,"mmmm yyyy") -> noviembre 2025
A42: 45972 | B42: Uber Transferencia -BBVA | C42: Ingreso | D42: 50000 | E42: Uber | G42: Naranja X | H42: =TEXT(A42,"mmmm yyyy") -> noviembre 2025
A43: 45975 | B43: Ganancias frasco | C43: Ingreso | D43: 66700 | E43: Frasco | G43: Naranja X | H43: =TEXT(A43,"mmmm yyyy") -> noviembre 2025
A44: 45975 | B44: Transferencia Fran | C44: Gasto | D44: 700000 | E44: Inversion | F44: Naranja X | H44: =TEXT(A44,"mmmm yyyy") -> noviembre 2025
A45: 45975 | B45: Seguro Auto | C45: Gasto | D45: 20000 | E45: Servicios | F45: Naranja X | H45: =TEXT(A45,"mmmm yyyy") -> noviembre 2025
A46: 45977 | B46: Bebe Devolucion | C46: Ingreso | D46: 80000 | E46: Prestamo | G46: Naranja X | H46: =TEXT(A46,"mmmm yyyy") -> noviembre 2025
A47: 45977 | B47: Caro Sueldo Noviembre | C47: Gasto | D47: 70000 | E47: Carolina | F47: Naranja X | H47: =TEXT(A47,"mmmm yyyy") -> noviembre 2025
A48: 45977 | B48: Nafta | C48: Gasto | D48: 54000 | E48: Combustible | F48: Naranja X | H48: =TEXT(A48,"mmmm yyyy") -> noviembre 2025
...

Sheet Proyeccion
B1: 45992 | C1: 46023 | D1: 46054 | E1: 46082 | F1: 46113 | G1: 46143 | H1: 46174 | I1: 46204 | J1: 46235 | K1: 46266 | L1: 46296 | M1: 46327 | N1: 46357
A2: Sueldo | B2: =SUMIFS(Contable!$D:$D,Contable!$H:$H, B$1,Contable!$E:$E, "sueldo",Contable!$C:$C,"Ingreso") -> 3248000 | C2: =SUMIFS(Contable!$D:$D,Contable!$H:$H, C$1,Contable!$E:$E, "sueldo") -> 2175700 | D2: =SUMIFS(Contable!$D:$D,Contable!$H:$H, D$1,Contable!$E:$E, "sueldo") -> 2177000 | E2: =SUMIFS(Contable!$D:$D,Contable!$H:$H, E$1,Contable!$E:$E, "sueldo") -> 2177235 | F2: =SUMIFS(Contable!$D:$D,Contable!$H:$H, F$1,Contable!$E:$E, "sueldo") -> 2314000 | G2: =SUMIFS(Contable!$D:$D,Contable!$H:$H, G$1,Contable!$E:$E, "sueldo") -> 2409000 | H2: =SUMIFS(Contable!$D:$D,Contable!$H:$H, H$1,Contable!$E:$E, "sueldo") -> 2306000 | I2: =SUMIFS(Contable!$D:$D,Contable!$H:$H, I$1,Contable!$E:$E, "sueldo") -> 3548376 | J2: =SUMIFS(Contable!$D:$D,Contable!$H:$H, J$1,Contable!$E:$E, "sueldo") -> 2434000 | ... M2: =SUMIFS(Contable!$D:$D,Contable!$H:$H, M$1,Contable!$E:$E, "sueldo") -> 0
A3: Gastos | B3: =SUMIFS(Contable!$D:$D, Contable!$H:$H, B$1, Contable!$E:$E, "Gastos",Contable!$C:$C,"Gasto") -> 110900 | C3: =SUMIFS(Contable!$D:$D, Contable!$H:$H, C$1, Contable!$E:$E, "Gastos",Contable!$C:$C,"Gasto") -> 406787 | D3: =SUMIFS(Contable!$D:$D, Contable!$H:$H, D$1, Contable!$E:$E, "Gastos",Contable!$C:$C,"Gasto") -> 516355 | E3: =SUMIFS(Contable!$D:$D, Contable!$H:$H, E$1, Contable!$E:$E, "Gastos",Contable!$C:$C,"Gasto") -> 25000 | F3: =SUMIFS(Contable!$D:$D, Contable!$H:$H, F$1, Contable!$E:$E, "Gastos") -> 512093 | G3: =SUMIFS(Contable!$D:$D, Contable!$H:$H, G$1, Contable!$E:$E, "Gastos") -> 842921 | H3: =SUMIFS(Contable!$D:$D, Contable!$H:$H, H$1, Contable!$E:$E, "Gastos") -> 453815.25 | I3: =SUMIFS(Contable!$D:$D, Contable!$H:$H, I$1, Contable!$E:$E, "Gastos") -> 246730 | J3: =SUMIFS(Contable!$D:$D, Contable!$H:$H, J$1, Contable!$E:$E, "Gastos") -> 352417 | K3: =SUMIFS(Contable!$D:$D, Contable!$H:$H, K$1, Contable!$E:$E, "Gastos") -> 0 | L3: =SUMIFS(Contable!$D:$D, Contable!$H:$H, L$1, Contable!$E:$E, "Gastos") -> 0 | M3: =SUMIFS(Finanzas!$C:$C, Finanzas!$F:$F, M$1, Finanzas!$E:$E, "Gastos") -> 0 | N3: =SUMIFS(Finanzas!$C:$C, Finanzas!$F:$F, N$1, Finanzas!$E:$E, "Gastos") -> 0
A4: Gastos Auto | B4: =SUMIFS(Contable!$D:$D,Contable!$H:$H, B$1,Contable!$E:$E, "Combustible",Contable!$C:$C,"Gasto")+SUMIFS(Contable!$D:$D,Contable!$H:$H,B$1,Contable!$E:$E, "Auto",Contable!$C:$C,"Gasto") -> 410000 | C4: =SUMIFS(Contable!$D:$D,Contable!$H:$H, C$1,Contable!$E:$E, "Combustible",Contable!$C:$C,"Gasto")+SUMIFS(Contable!$D:$D,Contable!$H:$H,C$1,Contable!$E:$E, "Auto",Contable!$C:$C,"Gasto") -> 360200 | D4: =SUMIFS(Contable!$D:$D,Contable!$H:$H, D$1,Contable!$E:$E, "Combustible",Contable!$C:$C,"Gasto")+SUMIFS(Contable!$D:$D,Contable!$H:$H,D$1,Contable!$E:$E, "Auto",Contable!$C:$C,"Gasto") -> 150000 | E4: =SUMIFS(Contable!$D:$D,Contable!$H:$H, E$1,Contable!$E:$E, "Combustible",Contable!$C:$C,"Gasto")+SUMIFS(Contable!$D:$D,Contable!$H:$H,E$1,Contable!$E:$E, "Auto",Contable!$C:$C,"Gasto") -> 88000 | F4: =SUMIFS(Contable!$D:$D,Contable!$H:$H, F$1,Contable!$E:$E, "Combustible",Contable!$C:$C,"Gasto")+SUMIFS(Contable!$D:$D,Contable!$H:$H,F$1,Contable!$E:$E, "Auto",Contable!$C:$C,"Gasto") -> 369000 | G4: =SUMIFS(Contable!$D:$D,Contable!$H:$H, G$1,Contable!$E:$E, "Combustible",Contable!$C:$C,"Gasto")+SUMIFS(Contable!$D:$D,Contable!$H:$H,G$1,Contable!$E:$E, "Auto",Contable!$C:$C,"Gasto") -> 70000 | H4: =SUMIFS(Contable!$D:$D,Contable!$H:$H, H$1,Contable!$E:$E, "Combustible",Contable!$C:$C,"Gasto")+SUMIFS(Contable!$D:$D,Contable!$H:$H,H$1,Contable!$E:$E, "Auto",Contable!$C:$C,"Gasto") -> 323000 | I4: =SUMIFS(Contable!$D:$D,Contable!$H:$H, I$1,Contable!$E:$E, "Combustible",Contable!$C:$C,"Gasto")+SUMIFS(Contable!$D:$D,Contable!$H:$H,I$1,Contable!$E:$E, "Auto",Contable!$C:$C,"Gasto") -> 726000 | J4: =SUMIFS(Contable!$D:$D,Contable!$H:$H, J$1,Contable!$E:$E, "Combustible",Contable!$C:$C,"Gasto")+SUMIFS(Contable!$D:$D,Contable!$H:$H,J$1,Contable!$E:$E, "Auto",Contable!$C:$C,"Gasto") -> 192000 | K4: =SUMIFS(Finanzas!$C:$C,Finanzas!$F:$F, K$1,Finanzas!$E:$E, "Combustible")+SUMIFS(Finanzas!$C:$C,Finanzas!$F:$F,K$1,Finanzas!$E:$E, "Auto") -> 0 | L4: =SUMIFS(Finanzas!$C:$C,Finanzas!$F:$F, L$1,Finanzas!$E:$E, "Combustible")+SUMIFS(Finanzas!$C:$C,Finanzas!$F:$F,L$1,Finanzas!$E:$E, "Auto") -> 0 | M4: =SUMIFS(Finanzas!$C:$C,Finanzas!$F:$F, M$1,Finanzas!$E:$E, "Combustible")+SUMIFS(Finanzas!$C:$C,Finanzas!$F:$F,M$1,Finanzas!$E:$E, "Auto") -> 0 | N4: =SUMIFS(Finanzas!$C:$C,Finanzas!$F:$F, N$1,Finanzas!$E:$E, "Combustible")+SUMIFS(Finanzas!$C:$C,Finanzas!$F:$F,N$1,Finanzas!$E:$E, "Auto") -> 0
A5: Eg Prestamo | B5: =SUMIFS(Contable!$D:$D,Contable!$H:$H,B$1,Contable!$E:$E, "Prestamo",Contable!$C:$C,"Gasto") -> 100000 | C5: =SUMIFS(Contable!$D:$D,Contable!$H:$H,C$1,Contable!$E:$E, "Prestamo",Contable!$C:$C,"Gasto") -> 80000 | D5: =SUMIFS(Contable!$D:$D,Contable!$H:$H,D$1,Contable!$E:$E, "Prestamo",Contable!$C:$C,"Gasto") -> 0 | E5: =SUMIFS(Contable!$D:$D,Contable!$H:$H,E$1,Contable!$E:$E, "Prestamo",Contable!$C:$C,"Gasto") -> 0 | F5: =SUMIFS(Contable!$D:$D,Contable!$H:$H,F$1,Contable!$E:$E, "Prestamo",Contable!$C:$C,"Gasto") -> 0 | G5: =SUMIFS(Contable!$D:$D,Contable!$H:$H,G$1,Contable!$E:$E, "Prestamo",Contable!$C:$C,"Gasto") -> 0 | H5: =SUMIFS(Contable!$D:$D,Contable!$H:$H,H$1,Contable!$E:$E, "Prestamo",Contable!$C:$C,"Gasto") -> 0 | I5: =SUMIFS(Contable!$D:$D,Contable!$H:$H,I$1,Contable!$E:$E, "Prestamo",Contable!$C:$C,"Gasto") -> 0 | ... K5: =SUMIFS(Contable!$D:$D,Contable!$H:$H,K$1,Contable!$E:$E, "Prestamo",Contable!$C:$C,"Gasto") -> 0 | L5: =SUMIFS(Finanzas!$C:$C,Finanzas!$F:$F,L$1,Finanzas!$E:$E, "Prestamo") -> 0 | M5: =SUMIFS(Finanzas!$C:$C,Finanzas!$F:$F,M$1,Finanzas!$E:$E, "Prestamo") -> 0 | N5: =SUMIFS(Finanzas!$C:$C,Finanzas!$F:$F,N$1,Finanzas!$E:$E, "Prestamo") -> 0
A6: Eg San Isidro | B6: =SUMIFS(Contable!$D:$D,Contable!$H:$H, B$1,Contable!$E:$E, "inversion",Contable!$C:$C,"Gasto") -> 475000 | C6: =SUMIFS(Contable!$D:$D,Contable!$H:$H, C$1,Contable!$E:$E, "inversion",Contable!$C:$C,"Gasto") -> 860000 | D6: =SUMIFS(Contable!$D:$D,Contable!$H:$H, D$1,Contable!$E:$E, "inversion",Contable!$C:$C,"Gasto") -> 880000 | E6: =SUMIFS(Contable!$D:$D,Contable!$H:$H, E$1,Contable!$E:$E, "inversion",Contable!$C:$C,"Gasto") -> 271000 | F6: =SUMIFS(Contable!$D:$D,Contable!$H:$H, F$1,Contable!$E:$E, "inversion",Contable!$C:$C,"Gasto") -> 1155000 | G6: =SUMIFS(Contable!$D:$D,Contable!$H:$H, G$1,Contable!$E:$E, "inversion",Contable!$C:$C,"Gasto") -> 630000 | H6: =SUMIFS(Contable!$D:$D,Contable!$H:$H, H$1,Contable!$E:$E, "inversion",Contable!$C:$C,"Gasto") -> 930000 | I6: =SUMIFS(Contable!$D:$D,Contable!$H:$H, I$1,Contable!$E:$E, "inversion",Contable!$C:$C,"Gasto") -> 1170000 | ... L6: =SUMIFS(Contable!$D:$D,Contable!$H:$H, L$1,Contable!$E:$E, "inversion",Contable!$C:$C,"Gasto") -> 0 | M6: =SUMIFS(Finanzas!$C:$C,Finanzas!$F:$F, M$1,Finanzas!$E:$E, "inversion") -> 0 | N6: =SUMIFS(Finanzas!$C:$C,Finanzas!$F:$F, N$1,Finanzas!$E:$E, "inversion") -> 0
A7: Eg Alexis | B7: =SUMIFS(Contable!$D:$D,Contable!$H:$H, B$1,Contable!$E:$E, "alexis",Contable!$C:$C,"Gasto") -> 300000 | C7: =SUMIFS(Contable!$D:$D,Contable!$H:$H, C$1,Contable!$E:$E, "alexis",Contable!$C:$C,"Gasto") -> 300000 | D7: =SUMIFS(Contable!$D:$D,Contable!$H:$H, D$1,Contable!$E:$E, "alexis",Contable!$C:$C,"Gasto") -> 400000 | E7: =SUMIFS(Contable!$D:$D,Contable!$H:$H, E$1,Contable!$E:$E, "alexis",Contable!$C:$C,"Gasto") -> 0 | F7: =SUMIFS(Contable!$D:$D,Contable!$H:$H, F$1,Contable!$E:$E, "alexis",Contable!$C:$C,"Gasto") -> 173000 | G7: =SUMIFS(Contable!$D:$D,Contable!$H:$H, G$1,Contable!$E:$E, "alexis",Contable!$C:$C,"Gasto") -> 0 | H7: =SUMIFS(Contable!$D:$D,Contable!$H:$H, H$1,Contable!$E:$E, "alexis",Contable!$C:$C,"Gasto") -> 0 | I7: =SUMIFS(Contable!$D:$D,Contable!$H:$H, I$1,Contable!$E:$E, "alexis",Contable!$C:$C,"Gasto") -> 154000 | ... M7: =SUMIFS(Contable!$D:$D,Contable!$H:$H, M$1,Contable!$E:$E, "alexis",Contable!$C:$C,"Gasto") -> 0 | N7: =SUMIFS(Finanzas!$C:$C,Finanzas!$F:$F, N$1,Finanzas!$E:$E, "alexis") -> 0
A8: Eg Servicios | B8: =SUMIFS(Contable!$D:$D,Contable!$H:$H, B$1,Contable!$E:$E, "servicios",Contable!$C:$C,"Gasto") -> 201200 | C8: =SUMIFS(Contable!$D:$D,Contable!$H:$H, C$1,Contable!$E:$E, "servicios",Contable!$C:$C,"Gasto") -> 44700 | D8: =SUMIFS(Contable!$D:$D,Contable!$H:$H, D$1,Contable!$E:$E, "servicios",Contable!$C:$C,"Gasto") -> 160988 | E8: =SUMIFS(Contable!$D:$D,Contable!$H:$H, E$1,Contable!$E:$E, "servicios",Contable!$C:$C,"Gasto") -> 296732 | F8: =SUMIFS(Contable!$D:$D,Contable!$H:$H, F$1,Contable!$E:$E, "servicios",Contable!$C:$C,"Gasto") -> 101900 | G8: =SUMIFS(Contable!$D:$D,Contable!$H:$H, G$1,Contable!$E:$E, "servicios",Contable!$C:$C,"Gasto") -> 93450 | H8: =SUMIFS(Contable!$D:$D,Contable!$H:$H, H$1,Contable!$E:$E, "servicios",Contable!$C:$C,"Gasto") -> 77201 | I8: =SUMIFS(Contable!$D:$D,Contable!$H:$H, I$1,Contable!$E:$E, "servicios",Contable!$C:$C,"Gasto") -> 277700 | ... L8: =SUMIFS(Contable!$D:$D,Contable!$H:$H, L$1,Contable!$E:$E, "servicios",Contable!$C:$C,"Gasto") -> 0 | M8: =SUMIFS(Finanzas!$C:$C,Finanzas!$F:$F, M$1,Finanzas!$E:$E, "servicios") -> 0 | N8: =SUMIFS(Finanzas!$C:$C,Finanzas!$F:$F, N$1,Finanzas!$E:$E, "servicios") -> 0
A9: Eg Tarjeta | B9: =SUMIFS(Contable!$D:$D,Contable!$H:$H, B$1,Contable!$E:$E, "tarjeta",Contable!$C:$C,"Gasto") -> 331043.75 | C9: =SUMIFS(Contable!$D:$D,Contable!$H:$H, C$1,Contable!$E:$E, "tarjeta",Contable!$C:$C,"Gasto") -> 0 | D9: =SUMIFS(Contable!$D:$D,Contable!$H:$H, D$1,Contable!$E:$E, "tarjeta",Contable!$C:$C,"Gasto") -> 222104 | E9: =SUMIFS(Contable!$D:$D,Contable!$H:$H, E$1,Contable!$E:$E, "tarjeta",Contable!$C:$C,"Gasto") -> 613155 | F9: =SUMIFS(Contable!$D:$D,Contable!$H:$H, F$1,Contable!$E:$E, "tarjeta",Contable!$C:$C,"Gasto") -> 436000 | G9: =SUMIFS(Contable!$D:$D,Contable!$H:$H, G$1,Contable!$E:$E, "tarjeta",Contable!$C:$C,"Gasto") -> 531100 | H9: =SUMIFS(Contable!$D:$D,Contable!$H:$H, H$1,Contable!$E:$E, "tarjeta",Contable!$C:$C,"Gasto") -> 366000 | I9: =SUMIFS(Contable!$D:$D,Contable!$H:$H, I$1,Contable!$E:$E, "tarjeta",Contable!$C:$C,"Gasto") -> 212000 | ... L9: =SUMIFS(Contable!$D:$D,Contable!$H:$H, L$1,Contable!$E:$E, "tarjeta",Contable!$C:$C,"Gasto") -> 0 | M9: =SUMIFS(Finanzas!$C:$C,Finanzas!$F:$F, M$1,Finanzas!$E:$E, "tarjeta") -> 0 | N9: =SUMIFS(Finanzas!$C:$C,Finanzas!$F:$F, N$1,Finanzas!$E:$E, "tarjeta") -> 0
A10: Eg Sueldos | B10: =SUMIFS(Contable!$D:$D,Contable!$H:$H, B$1,Contable!$E:$E, "Carolina",Contable!$C:$C,"Gasto") -> 75000 | C10: =SUMIFS(Contable!$D:$D,Contable!$H:$H, C$1,Contable!$E:$E, "Carolina",Contable!$C:$C,"Gasto") -> 0 | D10: =SUMIFS(Contable!$D:$D,Contable!$H:$H, D$1,Contable!$E:$E, "Carolina",Contable!$C:$C,"Gasto") -> 0 | E10: =SUMIFS(Contable!$D:$D,Contable!$H:$H, E$1,Contable!$E:$E, "Carolina",Contable!$C:$C,"Gasto") -> 65000 | F10: =SUMIFS(Contable!$D:$D,Contable!$H:$H, F$1,Contable!$E:$E, "Carolina",Contable!$C:$C,"Gasto") -> 65000 | G10: =SUMIFS(Contable!$D:$D,Contable!$H:$H, G$1,Contable!$E:$E, "Carolina",Contable!$C:$C,"Gasto") -> 65000 | H10: =SUMIFS(Contable!$D:$D,Contable!$H:$H, H$1,Contable!$E:$E, "Carolina",Contable!$C:$C,"Gasto") -> 70000 | I10: =SUMIFS(Contable!$D:$D,Contable!$H:$H, I$1,Contable!$E:$E, "Carolina",Contable!$C:$C,"Gasto") -> 100000 | ... M10: =SUMIFS(Contable!$D:$D,Contable!$H:$H, M$1,Contable!$E:$E, "Carolina",Contable!$C:$C,"Gasto") -> 0 | N10: =SUMIFS(Finanzas!$C:$C,Finanzas!$F:$F, N$1,Finanzas!$E:$E, "Carolina") -> 0
A11: Gastos ex(via, com) | B11: =SUMIFS(Contable!$D:$D,Contable!$H:$H, B$1,Contable!$E:$E, "Extra",Contable!$C:$C,"Gasto") -> 389900 | C11: =SUMIFS(Contable!$D:$D,Contable!$H:$H, C$1,Contable!$E:$E, "Extra",Contable!$C:$C,"Gasto") -> 0 | D11: =SUMIFS(Contable!$D:$D,Contable!$H:$H, D$1,Contable!$E:$E, "Extra",Contable!$C:$C,"Gasto") -> 1753000 | E11: =SUMIFS(Contable!$D:$D,Contable!$H:$H, E$1,Contable!$E:$E, "Extra",Contable!$C:$C,"Gasto") -> 126800 | F11: =SUMIFS(Contable!$D:$D,Contable!$H:$H, F$1,Contable!$E:$E, "Extra",Contable!$C:$C,"Gasto") -> 0 | G11: =SUMIFS(Contable!$D:$D,Contable!$H:$H, G$1,Contable!$E:$E, "Extra",Contable!$C:$C,"Gasto") -> 17000 | H11: =SUMIFS(Contable!$D:$D,Contable!$H:$H, H$1,Contable!$E:$E, "Extra",Contable!$C:$C,"Gasto") -> 228000 | I11: =SUMIFS(Contable!$D:$D,Contable!$H:$H, I$1,Contable!$E:$E, "Extra",Contable!$C:$C,"Gasto") -> 149500 | ... L11: =SUMIFS(Contable!$D:$D,Contable!$H:$H, L$1,Contable!$E:$E, "Extra",Contable!$C:$C,"Gasto") -> 0 | M11: =SUMIFS(Finanzas!$C:$C,Finanzas!$F:$F, M$1,Finanzas!$E:$E, "Extra") -> 0 | N11: =SUMIFS(Finanzas!$C:$C,Finanzas!$F:$F, N$1,Finanzas!$E:$E, "Extra") -> 0
A12: Ing Devoluciones | B12: =SUMIFS(Contable!$D:$D,Contable!$H:$H, B$1,Contable!$E:$E, "prestamo",Contable!$C:$C,"Ingreso") -> 0 | C12: =SUMIFS(Contable!$D:$D,Contable!$H:$H, C$1,Contable!$E:$E, "prestamo",Contable!$C:$C,"Ingreso") -> 473240 | D12: =SUMIFS(Contable!$D:$D,Contable!$H:$H, D$1,Contable!$E:$E, "prestamo",Contable!$C:$C,"Ingreso") -> 105000 | E12: =SUMIFS(Contable!$D:$D,Contable!$H:$H, E$1,Contable!$E:$E, "prestamo",Contable!$C:$C,"Ingreso") -> 411952 | F12: =SUMIFS(Contable!$D:$D,Contable!$H:$H, F$1,Contable!$E:$E, "prestamo",Contable!$C:$C,"Ingreso") -> 168000 | G12: =SUMIFS(Contable!$D:$D,Contable!$H:$H, G$1,Contable!$E:$E, "prestamo",Contable!$C:$C,"Ingreso") -> 55000 | H12: =SUMIFS(Contable!$D:$D,Contable!$H:$H, H$1,Contable!$E:$E, "prestamo",Contable!$C:$C,"Ingreso") -> 0 | I12: =SUMIFS(Contable!$D:$D,Contable!$H:$H, I$1,Contable!$E:$E, "prestamo",Contable!$C:$C,"Ingreso") -> 0 | ... L12: =SUMIFS(Contable!$D:$D,Contable!$H:$H, L$1,Contable!$E:$E, "prestamo",Contable!$C:$C,"Ingreso") -> 0 | M12: =SUMIFS(Finanzas!$B:$B,Finanzas!$F:$F, M$1,Finanzas!$E:$E, "prestamo") -> 0 | N12: =SUMIFS(Finanzas!$B:$B,Finanzas!$F:$F, N$1,Finanzas!$E:$E, "prestamo") -> 0
A13: Ing Trabajos Extras | B13: =SUMIFS(Contable!$D:$D,Contable!$H:$H, B$1,Contable!$E:$E, "uber",Contable!$C:$C,"Ingreso")+SUMIFS(Contable!$D:$D,Contable!$H:$H, B$1,Contable!$E:$E, "trabajo",Contable!$C:$C,"Ingreso") -> 453900 | C13: =SUMIFS(Contable!$D:$D,Contable!$H:$H, C$1,Contable!$E:$E, "uber",Contable!$C:$C,"Ingreso")+SUMIFS(Contable!$D:$D,Contable!$H:$H, C$1,Contable!$E:$E, "trabajo",Contable!$C:$C,"Ingreso") -> 0 | D13: =SUMIFS(Contable!$D:$D,Contable!$H:$H, D$1,Contable!$E:$E, "uber",Contable!$C:$C,"Ingreso")+SUMIFS(Contable!$D:$D,Contable!$H:$H, D$1,Contable!$E:$E, "trabajo",Contable!$C:$C,"Ingreso") -> 345209 | E13: =SUMIFS(Contable!$D:$D,Contable!$H:$H, E$1,Contable!$E:$E, "uber",Contable!$C:$C,"Ingreso")+SUMIFS(Contable!$D:$D,Contable!$H:$H, E$1,Contable!$E:$E, "trabajo",Contable!$C:$C,"Ingreso") -> 792 | F13: =SUMIFS(Contable!$D:$D,Contable!$H:$H, F$1,Contable!$E:$E, "uber",Contable!$C:$C,"Ingreso")+SUMIFS(Contable!$D:$D,Contable!$H:$H, F$1,Contable!$E:$E, "trabajo",Contable!$C:$C,"Ingreso") -> 3100 | G13: =SUMIFS(Contable!$D:$D,Contable!$H:$H, G$1,Contable!$E:$E, "uber",Contable!$C:$C,"Ingreso")+SUMIFS(Contable!$D:$D,Contable!$H:$H, G$1,Contable!$E:$E, "trabajo",Contable!$C:$C,"Ingreso") -> 0 | H13: =SUMIFS(Contable!$D:$D,Contable!$H:$H, H$1,Contable!$E:$E, "uber",Contable!$C:$C,"Ingreso")+SUMIFS(Contable!$D:$D,Contable!$H:$H, H$1,Contable!$E:$E, "trabajo",Contable!$C:$C,"Ingreso") -> 65000 | I13: =SUMIFS(Contable!$D:$D,Contable!$H:$H, I$1,Contable!$E:$E, "uber",Contable!$C:$C,"Ingreso")+SUMIFS(Contable!$D:$D,Contable!$H:$H, I$1,Contable!$E:$E, "trabajo",Contable!$C:$C,"Ingreso") -> 12000 | ... L13: =SUMIFS(Contable!$D:$D,Contable!$H:$H, L$1,Contable!$E:$E, "uber",Contable!$C:$C,"Ingreso")+SUMIFS(Contable!$D:$D,Contable!$H:$H, L$1,Contable!$E:$E, "trabajo",Contable!$C:$C,"Ingreso") -> 0 | M13: =SUMIFS(Finanzas!$B:$B,Finanzas!$F:$F, M$1,Finanzas!$E:$E, "uber")+SUMIFS(Finanzas!$B:$B,Finanzas!$F:$F, M$1,Finanzas!$E:$E, "trabajo") -> 0 | N13: =SUMIFS(Finanzas!$B:$B,Finanzas!$F:$F, N$1,Finanzas!$E:$E, "uber")+SUMIFS(Finanzas!$B:$B,Finanzas!$F:$F, N$1,Finanzas!$E:$E, "trabajo") -> 0
A14: Frascos | B14: =SUMIFS(Contable!$D:$D,Contable!$H:$H, B$1,Contable!$E:$E, "frasco",Contable!$C:$C,"Ingreso") -> 169520 | C14: =SUMIFS(Contable!$D:$D,Contable!$H:$H, C$1,Contable!$E:$E, "frasco",Contable!$C:$C,"Ingreso") -> 169747 | D14: =SUMIFS(Contable!$D:$D,Contable!$H:$H, D$1,Contable!$E:$E, "frasco",Contable!$C:$C,"Ingreso") -> 176561 | E14: =SUMIFS(Contable!$D:$D,Contable!$H:$H, E$1,Contable!$E:$E, "frasco",Contable!$C:$C,"Ingreso") -> 214251 | F14: =SUMIFS(Contable!$D:$D,Contable!$H:$H, F$1,Contable!$E:$E, "frasco",Contable!$C:$C,"Ingreso") -> 262000 | G14: =SUMIFS(Contable!$D:$D,Contable!$H:$H, G$1,Contable!$E:$E, "frasco",Contable!$C:$C,"Ingreso") -> 195643 | H14: =SUMIFS(Contable!$D:$D,Contable!$H:$H, H$1,Contable!$E:$E, "frasco",Contable!$C:$C,"Ingreso") -> 190000 | I14: =SUMIFS(Contable!$D:$D,Contable!$H:$H, I$1,Contable!$E:$E, "frasco",Contable!$C:$C,"Ingreso") -> 201000 | ... L14: =SUMIFS(Contable!$D:$D,Contable!$H:$H, L$1,Contable!$E:$E, "frasco",Contable!$C:$C,"Ingreso") -> 0 | M14: =SUMIFS(Finanzas!N:N,Finanzas!R:R, "Diciembre 2025",Finanzas!Q:Q, "frasco") -> 0 | N14: =SUMIFS(Finanzas!O:O,Finanzas!S:S, "Diciembre 2025",Finanzas!R:R, "frasco") -> 0
A15: Ingreso SanIsidro | B15: =SUMIFS(Contable!$D:$D,Contable!$H:$H, B$1,Contable!$E:$E, "Inversion",Contable!$C:$C,"Ingreso") -> 0 | C15: =SUMIFS(Contable!$D:$D,Contable!$H:$H, C$1,Contable!$E:$E, "Inversion",Contable!$C:$C,"Ingreso") -> 0 | D15: =SUMIFS(Contable!$D:$D,Contable!$H:$H, D$1,Contable!$E:$E, "Inversion",Contable!$C:$C,"Ingreso") -> 1723350 | E15: =SUMIFS(Contable!$D:$D,Contable!$H:$H, E$1,Contable!$E:$E, "Inversion",Contable!$C:$C,"Ingreso") -> 2857001 | F15: =SUMIFS(Contable!$D:$D,Contable!$H:$H, F$1,Contable!$E:$E, "Inversion",Contable!$C:$C,"Ingreso") -> 1973500 | G15: =SUMIFS(Contable!$D:$D,Contable!$H:$H, G$1,Contable!$E:$E, "Inversion",Contable!$C:$C,"Ingreso") -> 3631000 | H15: =SUMIFS(Contable!$D:$D,Contable!$H:$H, H$1,Contable!$E:$E, "Inversion",Contable!$C:$C,"Ingreso") -> 6827000 | I15: =SUMIFS(Contable!$D:$D,Contable!$H:$H, I$1,Contable!$E:$E, "Inversion",Contable!$C:$C,"Ingreso") -> 2434000 | ... L15: =SUMIFS(Contable!$D:$D,Contable!$H:$H, L$1,Contable!$E:$E, "Inversion",Contable!$C:$C,"Ingreso") -> 0 | M15: =SUMIFS(Finanzas!$B:$B,Finanzas!$F:$F, M$1,Finanzas!$E:$E, "Inversion") -> 0 | N15: =SUMIFS(Finanzas!$B:$B,Finanzas!$F:$F, N$1,Finanzas!$E:$E, "Inversion") -> 0
A16: Ingreso Consultoria | B16: =SUMIFS(Contable!$D:$D,Contable!$H:$H, B$1,Contable!$E:$E, "Consultoria",Contable!$C:$C,"Ingreso") -> 0 | C16: =SUMIFS(Contable!$D:$D,Contable!$H:$H, C$1,Contable!$E:$E, "Consultoria",Contable!$C:$C,"Ingreso") -> 0 | D16: =SUMIFS(Contable!$D:$D,Contable!$H:$H, D$1,Contable!$E:$E, "Consultoria",Contable!$C:$C,"Ingreso") -> 0 | E16: =SUMIFS(Contable!$D:$D,Contable!$H:$H, E$1,Contable!$E:$E, "Consultoria",Contable!$C:$C,"Ingreso") -> 0 | F16: =SUMIFS(Contable!$D:$D,Contable!$H:$H, F$1,Contable!$E:$E, "Consultoria",Contable!$C:$C,"Ingreso") -> 0 | G16: =SUMIFS(Contable!$D:$D,Contable!$H:$H, G$1,Contable!$E:$E, "Consultoria",Contable!$C:$C,"Ingreso") -> 0 | H16: =SUMIFS(Contable!$D:$D,Contable!$H:$H, H$1,Contable!$E:$E, "Consultoria",Contable!$C:$C,"Ingreso") -> 0 | I16: =SUMIFS(Contable!$D:$D,Contable!$H:$H, I$1,Contable!$E:$E, "Consultoria",Contable!$C:$C,"Ingreso") -> 390000 | ... N16: =SUMIFS(Contable!$D:$D,Contable!$H:$H, N$1,Contable!$E:$E, "Consultoria",Contable!$C:$C,"Ingreso") -> 0
A17: Total Ingresos | B17: =SUM(B12:B16)+B2 -> 3871420 | C17: =SUM(C12:C16)+C2 -> 2818687 | D17: =SUM(D12:D16)+D2 -> 4527120 | E17: =SUM(E12:E16)+E2 -> 5661231 | F17: =SUM(F12:F16)+F2 -> 4720600 | G17: =SUM(G12:G16)+G2 -> 6290643 | H17: =SUM(H12:H16)+H2 -> 9388000 | I17: =SUM(I12:I16)+I2 -> 6585376 | J17: =SUM(J12:J16)+J2 -> 3590821 | K17: =SUM(K12:K15)+K2 -> 0 | L17: =SUM(L12:L15)+L2 -> 0 | M17: =SUM(M12:M15)+M2 -> 0 | N17: =SUM(N12:N15)+N2 -> 0
A18: Total egresos | B18: =SUM(B3:B11) -> 2393043.8 | C18: =SUM(C3:C11) -> 2051687 | D18: =SUM(D3:D11) -> 4082447 | E18: =SUM(E3:E11) -> 1485687 | F18: =SUM(F3:F11) -> 2811993 | G18: =SUM(G3:G11) -> 2249471 | H18: =SUM(H3:H11) -> 2448016.2 | I18: =SUM(I3:I11) -> 3035930 | ... N18: =SUM(N3:N11) -> 0
A19: Total | B19: =B17-B18 -> 1478376.2 | C19: =C17-C18 -> 767000 | D19: =D17-D18 -> 444673 | E19: =E17-E18 -> 4175544 | F19: =F17-F18 -> 1908607 | G19: =G17-G18 -> 4041172 | H19: =H17-H18 -> 6939983.8 | I19: =I17-I18 -> 3549446 | ... M19: =M17-M18 -> 0 | N19: =N2-SUM(N3:N11)+SUM(N12:N15) -> 0
A20: acumulado | B20: =B19 -> 1478376.2 | C20: =C19+B20 -> 2245376.2 | D20: =D19+C20 -> 2690049.2 | E20: =E19+D20 -> 6865593.2 | F20: =F19+E20 -> 8774200.2 | G20: =G19+F20 -> 12815372 | H20: =H19+G20 -> 19755356 | I20: =I19+H20 -> 23304802 | J20: =J19+I20 -> 25731721 | ... N20: =N19+M20 -> 25731721
A22: Egresos Personales | B22: =B3+B4+B5+B7+B8+B9+B10+B11 -> 1918043.8 | C22: =C3+C4+C5+C7+C8+C9+C10+C11 -> 1191687 | D22: =D3+D4+D5+D7+D8+D9+D10+D11 -> 3202447 | E22: =E3+E4+E5+E7+E8+E9+E10+E11 -> 1214687 | F22: =F3+F4+F5+F7+F8+F9+F10+F11 -> 1656993 | G22: =G3+G4+G5+G7+G8+G9+G10+G11 -> 1619471 | H22: =H3+H4+H5+H7+H8+H9+H10+H11 -> 1518016.2 | I22: =I3+I4+I5+I7+I8+I9+I10+I11 -> 1865930 | ... O22: =O3+O4+O5+O7+O8+O9+O10+O11 -> 0
H25: 2618000 | I25: =H25*1.037 -> 2714866 | J25: =I25*1.02 -> 2769163.3 | K25: =J25*1.016 -> 2813469.9 | L25: =K25*1.03 -> 2897874 | M25: =L25*1.02 -> 2955831.5 | N25: =M25*1.016 -> 3003124.8

Sheet San Isidro
G1: Prestamos PAPA | H1: 700000
A2: Concepto | B2: Pagos | C2: Fecha | D2: Tipo | E2: Columna 1 | G2: Prestamos PAPA | H2: 1000000
A3: Tierras de Ramirez y demas | B3: 920000 | C3: 45870 | D3: Arriendo | G3: Prestamos PAPA | H3: 100000
A4: Tierras de Guri | B4: 450000 | C4: 45870 | D4: Arriendo | H4: =1800000 -> 1800000
A5: Venenos y remedios | B5: =1260000 -> 1260000 | C5: 45870 | D5: Insumos | G5: Totales
A6: Agosto Gago | B6: 180000 | C6: 45904 | D6: Sueldos | E6: =B6/20000 -> 9 | G6: Sueldos | H6: =SUMIF(D:D, "Sueldos", B:B) -> 9231000
A7: Agosto Fran | B7: 160000 | C7: 45915 | D7: Sueldos | E7: =B7/20000 -> 8 | G7: Arriendo | H7: =SUMIF(D:D, "Arriendo", B:B) -> 1370000
A8: Septiembre Fran | B8: 450000 | C8: 45939 | D8: Sueldos | E8: =B8/25000 -> 18 | G8: Insumos | H8: =SUMIF(D:D, "Insumos", B:B) -> 1513000
A9: Septiembre Raul | B9: 400000 | C9: 45939 | D9: Sueldos | E9: =B9/25000 -> 16 | G9: Todo | H9: =SUM(H6:H8) -> 12114000
A10: Octubre Mama | B10: 62500 | C10: 45952 | D10: Sueldos | E10: =B10/25000 -> 2.5
A11: Octubre payo | B11: 125000 | C11: 45952 | D11: Sueldos | E11: =B11/25000 -> 5 | G11: =300000*11 -> 3300000 | H11: =360*30000 -> 10800000
A12: Jose Octubre | B12: 125000 | C12: 45955 | D12: Sueldos | E12: =B12/25000 -> 5 | H12: =SUMIF(D:D, "Arriendo", B:B) -> 1370000
A13: Coadyudante | B13: 63000 | C13: 45957 | D13: Insumos
A14: Mochila Fumigar | B14: 190000 | C14: 45957 | D14: Insumos
A15: Raul Octubre | B15: 350000 | C15: 45966 | D15: Sueldos | E15: =B15/25000 -> 14 | H15: =SUMIF(D:D, "Insumos", B:B) -> 1513000
A16: Fran Octubre | B16: 475000 | C16: 45971 | D16: Sueldos | E16: =B16/25000 -> 19 | H16: =SUM(H11:H15) -> 13683000
A17: Raul Noviembre | B17: 375000 | C17: 45995 | D17: Sueldos | E17: =B17/25000 -> 15
A18: Fran Noviembre | B18: 437500 | C18: 45995 | D18: Sueldos | E18: =B18/25000 -> 17.5
A19: Raul Adelanto Diciembre | B19: 100000 | C19: 46014 | D19: Sueldos | E19: =B19/25000 -> 4
A20: Bomba Diciembre | B20: 437500 | C20: 46028 | D20: Sueldos | E20: =B20/25000 -> 17.5 | H20: =360*30000 -> 10800000
A21: Raul Diciembre | B21: 460000 | C21: 46028 | D21: Sueldos | E21: 17.5
A22: Broder Enero | B22: 337500 | C22: 46072 | D22: Sueldos | E22: =B22/25000 -> 13.5
A23: Raul Enero | B23: =25000*10 -> 250000 | C23: 46073 | D23: Sueldos | E23: =B23/25000 -> 10
A24: Raul Febrero | B24: 126000 | C24: 46091 | D24: Sueldos | E24: =B24/28000 -> 4.5
A25: Broden Febrero | B25: 495000 | C25: 46091 | D25: Sueldos | E25: =B25/30000 -> 16.5
A26: Broden Marzo | B26: 555000 | C26: 46118 | D26: Sueldos | E26: =B26/30000 -> 18.5
A27: Gago Marzo | B27: 600000 | C27: 46118 | D27: Sueldos | E27: =B27/30000 -> 20
A28: Bomba Abril | B28: 525000 | C28: 46151 | D28: Sueldos | E28: =B28/30000 -> 17.5
A29: Raul Abril | B29: 105000 | C29: 46151 | D29: Sueldos | E29: =B29/30000 -> 3.5
A30: Raul Mayo | B30: 495000 | C30: 46183 | D30: Sueldos | E30: =B30/30000 -> 16.5
A31: Bomba Mayo | B31: 435000 | C31: 46184 | D31: Sueldos | E31: =B31/30000 -> 14.5
A32: Bomba Junio | B32: 735000 | C32: 46212 | D32: Sueldos | E32: =B32/30000 -> 24.5
A33: Raul Junio | B33: 435000 | C33: 46214 | D33: Sueldos | E33: =B33/30000 -> 14.5
E34: =B34/30000 -> 0
E35: =B35/30000 -> 0
E36: =B36/30000 -> 0
E37: =B37/30000 -> 0
E38: =B38/30000 -> 0
E39: =B39/30000 -> 0
E40: =B40/30000 -> 0
...

Sheet Liquidacion Sueldos
A2: Concepto | B2: Valor ($) | D2: Concepto | E2: Valor ($)
A3: Precio unitario por día | B3: 25000 | D3: Precio unitario por día | E3: 25000
A4: Cantidad de días trabajados | B4: 18 | D4: Cantidad de días trabajados | E4: 16
A5: Total * Cantidad dias trabajados | B5: =B3*B4 -> 450000 | D5: Total * Cantidad dias trabajados | E5: 400000
A6: Adelanto Sergio | B6: -150000 | D6: Adelanto Sergio | E6: -180000
A7: Adelanto Alexis | B7: -160000 | D7: Total neto a cobrar | E7: 220000
A8: Total neto a cobrar | B8: =B5+B6+B7 -> 140000
A12: Concepto | B12: Valor ($) | D12: Concepto | E12: Valor ($)
A13: Precio unitario por día | B13: 25000 | D13: Precio unitario por día | E13: 25000
A14: Cantidad de días trabajados | B14: 5 | D14: Cantidad de días trabajados | E14: 5
A15: Total * Cantidad dias trabajados | B15: =B13*B14 -> 125000 | D15: Total * Cantidad dias trabajados | E15: =E13*E14 -> 125000
A16: Adelanto Sergio | B16: -25000
A17: Total neto a cobrar | B17: =B15+B16 -> 100000 | D17: Total neto a cobrar | E17: =E15+E16 -> 125000
A20: Concepto | B20: Valor ($) | D20: Concepto | E20: Valor ($)
A21: Precio unitario por día | B21: 25000 | D21: Precio unitario por día | E21: 25000
A22: Cantidad de días trabajados | B22: 19 | D22: Cantidad de días trabajados | E22: 14
A23: Total * Cantidad dias trabajados | B23: =B21*B22 -> 475000 | D23: Total * Cantidad dias trabajados | E23: =E21*E22 -> 350000
A24: Deuda Computadora | B24: -260000 | D24: Total neto a cobrar | E24: =E22*E21 -> 350000
A26: Total neto a cobrar | B26: =B23+B24+B25 -> 215000
A29: Costo de grafica | B29: 829000
A30: Bomba paso tranferencia | B30: 129000 | D30: Concepto | E30: Valor ($)
A31: Alexia debia a bomba | B31: 215000 | D31: Precio unitario por día | E31: 25000
A32: Trabajado Noviembre bomba | B32: 437500 | D32: Cantidad de días trabajados | E32: 15
A33: Deuda restante | B33: =B29-B30-B31-B32 -> 47500 | D33: Total * Cantidad dias trabajados | E33: =E31*E32 -> 375000
D34: Total neto a cobrar | E34: =E32*E31 -> 375000
A36: Concepto | B36: Valor ($)
A37: Precio unitario por día | B37: 25000 | D37: Concepto | E37: Valor ($)
A38: Cantidad de días trabajados | B38: 17.5 | D38: Precio unitario por día | E38: 25000
A39: Total * Cantidad dias trabajados | B39: =B37*B38 -> 437500 | D39: Cantidad de días trabajados | E39: 16
D40: Precio paleada | E40: 40000
D41: Cantidad paleada | E41: 1.5
A42: Total neto a cobrar | B42: =B39+B40 -> 437500 | D42: Total * Cantidad dias trabajados | E42: =E38*E39+E40*E41 -> 460000
D43: Total neto a cobrar | E43: 460000
A46: Concepto | B46: Valor ($)
A47: Precio unitario por día | B47: 25000
A48: Cantidad de días trabajados | B48: 17.5
A49: Total * Cantidad dias trabajados | B49: =B47*B48 -> 437500
A50: Grafica deuda | B50: 47500
A51: Adelanto Poma 2 Diciembre | B51: 90000
A52: Total neto a cobrar | B52: =B49-B50-B51 -> 300000
...

Sheet Produccion
A1: Fecha | B1: Cliente | C1: Cosechero | D1: Cantidad (bolsas) | E1: Precio Unit | F1: Total | G1: Alexis | H1: Estado | I1: Columna 1
A2: 46051 | B2: Chocobar | C2: Raul | D2: 50 | E2: 5500 | F2: =D2*E2 -> 275000 | G2: =F2/4 -> 68750 | H2: Cobrado | I2: =F2*0.5 -> 137500
A3: 46053 | B3: Guido Inca | C3: Raul | D3: 48 | E3: 5300 | F3: =D3*E3 -> 254400 | G3: =F3/4 -> 63600 | H3: Cobrado | I3: =F3*0.5 -> 127200
A4: 46058 | B4: Chocobar | C4: Raul | D4: 100 | E4: 6000 | F4: =D4*E4 -> 600000 | G4: =F4/4 -> 150000 | H4: Cobrado | I4: =F4*0.5 -> 300000
A5: 46059 | B5: Guido Inca | C5: Raul | D5: 100 | E5: 5000 | F5: =D5*E5 -> 500000 | G5: =F5/4 -> 125000 | H5: Cobrado | I5: =F5*0.5 -> 250000
A6: 46062 | B6: Jorge Funes | C6: Raul | D6: 100 | E6: 5500 | F6: =D6*E6 -> 550000 | G6: =F6/4 -> 137500 | H6: Cobrado | I6: =F6*0.5 -> 275000
A7: 46063 | B7: Chocobar | C7: Raul | D7: 80 | E7: 6000 | F7: =D7*E7 -> 480000 | G7: =F7/4 -> 120000 | H7: Cobrado | I7: =F7*0.5 -> 240000
A8: 46064 | B8: Guido Inca | C8: Sociedad | D8: 100 | E8: 5000 | F8: =D8*E8 -> 500000 | G8: =F8/2 -> 250000 | H8: Cobrado
A9: 46068 | B9: Funes | C9: Sociedad | D9: 200 | E9: 4500 | F9: =D9*E9 -> 900000 | G9: =F9/2 -> 450000 | H9: Cobrado
A10: 46074 | B10: Guido Inca | C10: Sociedad | D10: 50 | E10: 4500 | F10: =D10*E10 -> 225000 | G10: =F10/2 -> 112500 | H10: Cobrado
A11: 46078 | B11: Chaves | C11: Sociedad | D11: 100 | E11: 4000 | F11: =D11*E11 -> 400000 | G11: =F11/2 -> 200000 | H11: Cobrado
A12: 46078 | B12: Ivan Inca | C12: Sociedad | D12: 150 | E12: 4500 | F12: =D12*E12 -> 675000 | G12: =F12/2 -> 337500 | H12: Cobrado
A13: 46081 | B13: Guido Inca | C13: Sociedad | D13: 400 | E13: 4500 | F13: =D13*E13 -> 1800000 | G13: =F13/2 -> 900000 | H13: Cobrado
A14: 46084 | B14: Guido Inca | C14: Sociedad | D14: 294 | E14: 4000 | F14: =D14*E14 -> 1176000 | G14: =F14/2 -> 588000 | H14: Cobrado
A15: 46091 | B15: Guido Inca | C15: Sociedad | D15: 146 | E15: 4000 | F15: =D15*E15 -> 584000 | G15: =F15/2 -> 292000 | H15: Cobrado
A16: 46092 | B16: Chaves | C16: Sociedad | D16: 120 | E16: 4000 | F16: =D16*E16 -> 480000 | G16: =F16/2 -> 240000 | H16: Cobrado
A17: 46095 | B17: Guido Inca | C17: Sociedad | D17: 246 | E17: 4000 | F17: =D17*E17 -> 984000 | G17: =F17/2 -> 492000 | H17: Cobrado
A18: 46099 | B18: Guido Inca | C18: Sociedad | D18: 84 | E18: 4500 | F18: =D18*E18 -> 378000 | G18: =F18/2 -> 189000 | H18: Cobrado
A19: 46102 | B19: Guido Inca | C19: Sociedad | D19: 130 | E19: 4500 | F19: =D19*E19 -> 585000 | G19: =F19/2 -> 292500 | H19: Cobrado
A20: 46106 | B20: Guido Inca | C20: Sociedad | D20: 196.5 | E20: 4500 | F20: =D20*E20 -> 884250 | G20: =F20/2 -> 442125 | H20: Cobrado
A21: 46107 | B21: Ivan Inca | C21: Sociedad | D21: 140 | E21: 4500 | F21: =D21*E21 -> 630000 | G21: =F21/2 -> 315000 | H21: Cobrado | J21: ok
A22: 46109 | B22: Guido Inca | C22: Sociedad | D22: 165 | E22: 4500 | F22: =D22*E22 -> 742500 | G22: =F22/2 -> 371250 | H22: Cobrado
A23: 46114 | B23: Guido Inca | C23: Raul | D23: 195 | E23: 4500 | F23: =D23*E23 -> 877500 | G23: =F23*0.2 -> 175500 | H23: Cobrado | I23: =F23*0.5 -> 438750 | J23: ok | K23: =SUM(G23:G25) -> 740400
A24: 46114 | B24: Guido Inca | C24: Raul | D24: 200 | E24: 7000 | F24: =D24*E24 -> 1400000 | G24: =F24*0.2 -> 280000 | H24: Cobrado | I24: =F24*0.6 -> 840000 | J24: ok
A25: 46114 | B25: Guido Inca | C25: Raul | D25: 203.5 | E25: 7000 | F25: =D25*E25 -> 1424500 | G25: =F25*0.2 -> 284900 | H25: Cobrado | I25: =F25*0.6 -> 854700 | J25: ok
A26: 46127 | B26: Guido Inca | C26: Sociedad | D26: 100 | E26: 7000 | F26: =D26*E26 -> 700000 | G26: =F26/2 -> 350000 | H26: Cobrado | J26: ok | K26: =G26 -> 350000
A27: 46130 | B27: Guido Inca | C27: Sociedad | D27: 143 | E27: 7000 | F27: =D27*E27 -> 1001000 | G27: =F27/2 -> 500500 | H27: Cobrado | J27: ok | K27: =G27 -> 500500
A28: 46134 | B28: Guido Inca | C28: Sociedad | D28: 150 | E28: 6000 | F28: =D28*E28 -> 900000 | G28: =F28/2 -> 450000 | H28: Cobrado | J28: ok | K28: =G28 -> 450000
A29: 46137 | B29: Guido Inca | C29: Sociedad | D29: 240 | E29: 6000 | F29: =D29*E29 -> 1440000 | G29: =F29/2 -> 720000 | H29: Cobrado | J29: ok | K29: =G29 -> 720000
A30: 46140 | B30: Chocobar | C30: Sociedad | D30: 50 | E30: 7500 | F30: =D30*E30 -> 375000 | G30: =F30/2 -> 187500 | H30: Cobrado | J30: =G30 -> 187500 | K30: =SUM(K26:K29)-500 -> 2020000 | L30: =K30*2 -> 4040000
A31: 46141 | B31: Chaves | C31: Sociedad | D31: 100 | E31: 6000 | F31: =D31*E31 -> 600000 | G31: =F31/2 -> 300000 | H31: Cobrado | J31: =G31 -> 300000
A32: 46142 | B32: Guido Inca | C32: Sociedad | D32: 200 | E32: 6000 | F32: =D32*E32 -> 1200000 | G32: =F32/2 -> 600000
A33: 46151 | B33: Chocobar | C33: Sociedad | D33: 100 | E33: 7500 | F33: =D33*E33 -> 750000 | G33: =F33/2 -> 375000 | H33: Cobrado | J33: =G33 -> 375000
A34: 46156 | B34: Chocobar | C34: Sociedad | D34: 50 | E34: 9000 | F34: =D34*E34 -> 450000 | G34: =F34/2 -> 225000 | H34: Cobrado | J34: =G34 -> 225000
A35: 46157 | B35: Guido Inca | C35: Sociedad | D35: 50 | E35: 9000 | F35: =D35*E35 -> 450000 | G35: =F35/2 -> 225000 | H35: Cobrado | J35: =G35 -> 225000 | L35: TOTAL = | M35: =K23+K30+K38 -> 4922900
A36: 46158 | B36: Chocobar | C36: Sociedad | D36: 100 | E36: 8000 | F36: 800000 | G36: 400000 | H36: Cobrado | J36: =G36 -> 400000 | M36: 3900000
A37: 46161 | B37: Chocobar | C37: Sociedad | D37: 50 | E37: 10000 | F37: =D37*E37 -> 500000 | G37: =F37/2 -> 250000 | H37: Cobrado | M37: =M35-M36 -> 1022900
A38: 46162 | B38: Guido Inca | C38: Sociedad | D38: 100 | E38: 9000 | F38: =D38*E38 -> 900000 | G38: =F38/2 -> 450000 | H38: Cobrado | J38: =G38 -> 450000 | K38: =SUM(J30:J38) -> 2162500
A39: 46163 | B39: Chocobar | C39: Sociedad | D39: 99 | E39: 10000 | F39: =D39*E39 -> 990000 | G39: =F39/2 -> 495000 | H39: Cobrado
A40: 46164 | B40: Guido Inca | C40: Sociedad | D40: 90 | E40: 9000 | F40: =D40*E40 -> 810000 | G40: =F40/2 -> 405000
...

Sheet Finanzas
A2: Concepto | B2: Entrada | C2: Gastos | D2: Fecha | E2: Concepto 2 | F2: Mes | G2: Columna 1 | H2: Column 8 | I2: Mes | J2: Total Gastos | K2: TotalIngresos | L2: Balance | M2: Frascos | N2: Sueldo
A3: Aplicacion Inicial Liquido | B3: 6930000 | D3: 45934 | E3: =IFERROR(__xludf.DUMMYFUNCTION("REGEXEXTRACT(A3,""[A-Za-z]+"")"),"Aplicacion") -> Aplicacion | F3: =TEXT(D3,"mmmm yyyy") -> octubre 2025 | G3: =IF(B2<>"", B2, IF(C2<>"", -C2, "")) -> Entrada | I3: cctubre | J3: =SUMIF(F:F,"octubre 2025",C:C) -> 3408169 | K3: =SUMIF(F:F,"octubre 2025",B:B) -> 9311000 | L3: =K3-J3 -> 5902831 | M3: =SUMIFS(B:B, F:F, "octubre 2025", E:E, "Sueldos") -> 0 | N3: =SUMIFS(B:B, F:F, "octubre 2025", E:E, "Sueldo") -> 2152000
A4: Uber | B4: 147000 | D4: 45936 | E4: =IFERROR(__xludf.DUMMYFUNCTION("REGEXEXTRACT(A4,""[A-Za-z]+"")"),"Uber") -> Uber | F4: =TEXT(D4,"mmmm yyyy") -> octubre 2025 | G4: =IF(B3<>"", B3, IF(C3<>"", -C3, "")) -> 6930000 | H4: =IF(G4="", "", IF(G4>0, "Ingreso", "Gasto")) -> Ingreso | I4: noviembre | J4: =SUMIF(F:F,"noviembre 2025",C:C) -> 1886600 | K4: =SUMIF(F:F,"noviembre 2025",B:B) -> 2383770 | L4: =K4-J4 -> 497170 | M4: =SUMIFS(B:B, F:F, "Noviembre 2025", E:E, "Frasco") -> 133180 | N4: =SUMIFS(B:B, F:F, "Noviembre 2025", E:E, "Sueldo") -> 2070000
A5: Gastos varios, adelanto celu, milas y corte de pelo | C5: 30000 | D5: 45937 | E5: =IFERROR(__xludf.DUMMYFUNCTION("REGEXEXTRACT(A5,""[A-Za-z]+"")"),"Gastos") -> Gastos | F5: =TEXT(D5,"mmmm yyyy") -> octubre 2025 | G5: =IF(B4<>"", B4, IF(C4<>"", -C4, "")) -> 147000 | H5: =IF(G5="", "", IF(G5>0, "Ingreso", "Gasto")) -> Ingreso | I5: diciembre | J5: =SUMIF(F:F,"diciembre 2025",C:C) -> 2393043.8 | K5: =SUMIF(F:F,"diciembre 2025",B:B) -> 3871420 | L5: =K5-J5 -> 1478376.2 | M5: =SUMIFS(B:B, F:F, "Diciembre 2025", E:E, "Frasco") -> 169520 | N5: =SUMIFS(B:B, F:F, "Diciembre 2025", E:E, "Sueldo") -> 3248000
A6: Sueldo Septiembre | B6: 2152000 | D6: 45938 | E6: =IFERROR(__xludf.DUMMYFUNCTION("REGEXEXTRACT(A6,""[A-Za-z]+"")"),"Sueldo") -> Sueldo | F6: =TEXT(D6,"mmmm yyyy") -> octubre 2025 | G6: =IF(B5<>"", B5, IF(C5<>"", -C5, "")) -> -30000 | H6: =IF(G6="", "", IF(G6>0, "Ingreso", "Gasto")) -> Gasto | I6: enero | J6: =SUMIF(F:F,"enero 2026",C:C) -> 2077687 | K6: =SUMIF(F:F,"enero 2026",B:B) -> 2820687 | L6: =K6-J6 -> 743000 | M6: =SUMIFS(B:B, F:F, "enero 2026", E:E, "Frasco") -> 169747 | N6: =SUMIFS(B:B, F:F, "enero 2026", E:E, "Sueldo") -> 2149700
A7: Transferencia Sergio | C7: 330000 | D7: 45939 | E7: Inversion | F7: =TEXT(D7,"mmmm yyyy") -> octubre 2025 | G7: =IF(B6<>"", B6, IF(C6<>"", -C6, "")) -> 2152000 | H7: =IF(G7="", "", IF(G7>0, "Ingreso", "Gasto")) -> Ingreso
A8: Transferencia Raul Suares Septtiembre | C8: 220000 | D8: 45939 | E8: Inversion | F8: =TEXT(D8,"mmmm yyyy") -> octubre 2025 | G8: =IF(B7<>"", B7, IF(C7<>"", -C7, "")) -> -330000 | H8: =IF(G8="", "", IF(G8>0, "Ingreso", "Gasto")) -> Gasto
A9: Pago Seguro Auto | C9: 20000 | D9: 45942 | E9: Servicios | F9: =TEXT(D9,"mmmm yyyy") -> octubre 2025 | G9: =IF(B8<>"", B8, IF(C8<>"", -C8, "")) -> -220000 | H9: =IF(G9="", "", IF(G9>0, "Ingreso", "Gasto")) -> Gasto
A10: Pago Cuota Regalo 1/2 Pamela Saravia | C10: 30000 | D10: 45942 | E10: Gastos | F10: =TEXT(D10,"mmmm yyyy") -> octubre 2025 | G10: =IF(B9<>"", B9, IF(C9<>"", -C9, "")) -> -20000 | H10: =IF(G10="", "", IF(G10>0, "Ingreso", "Gasto")) -> Gasto
A11: Gastos Finde | C11: 40000 | D11: 45942 | E11: =IFERROR(__xludf.DUMMYFUNCTION("REGEXEXTRACT(A11,""[A-Za-z]+"")"),"Gastos") -> Gastos | F11: =TEXT(D11,"mmmm yyyy") -> octubre 2025 | G11: =IF(B10<>"", B10, IF(C10<>"", -C10, "")) -> -30000 | H11: =IF(G11="", "", IF(G11>0, "Ingreso", "Gasto")) -> Gasto
A12: Modulo Celular A02s | C12: 25000 | D12: 45943 | E12: Gastos | F12: =TEXT(D12,"mmmm yyyy") -> octubre 2025 | G12: =IF(B11<>"", B11, IF(C11<>"", -C11, "")) -> -40000 | H12: =IF(G12="", "", IF(G12>0, "Ingreso", "Gasto")) -> Gasto
A13: Devolucion Cuota Bebe 2/3 | B13: 82000 | D13: 45943 | E13: Prestamo | F13: =TEXT(D13,"mmmm yyyy") -> octubre 2025 | G13: =IF(B12<>"", B12, IF(C12<>"", -C12, "")) -> -25000 | H13: =IF(G13="", "", IF(G13>0, "Ingreso", "Gasto")) -> Gasto
A14: Gastos Combustible | C14: 60000 | D14: 45943 | E14: Combustible | F14: =TEXT(D14,"mmmm yyyy") -> octubre 2025 | G14: =IF(B13<>"", B13, IF(C13<>"", -C13, "")) -> 82000 | H14: =IF(G14="", "", IF(G14>0, "Ingreso", "Gasto")) -> Ingreso
A15: Gastos Finde Semana | C15: 60000 | D15: 45952 | E15: =IFERROR(__xludf.DUMMYFUNCTION("REGEXEXTRACT(A15,""[A-Za-z]+"")"),"Gastos") -> Gastos | F15: =TEXT(D15,"mmmm yyyy") -> octubre 2025 | G15: =IF(B14<>"", B14, IF(C14<>"", -C14, "")) -> -60000 | H15: =IF(G15="", "", IF(G15>0, "Ingreso", "Gasto")) -> Gasto
A16: Pago total de tarjeta Naranja X Cuotas | C16: 513000 | D16: 45952 | E16: Tarjeta | F16: =TEXT(D16,"mmmm yyyy") -> octubre 2025 | G16: =IF(B15<>"", B15, IF(C15<>"", -C15, "")) -> -60000 | H16: =IF(G16="", "", IF(G16>0, "Ingreso", "Gasto")) -> Gasto
A17: Payo Transferencia Trabajo 4 dias | C17: 100000 | D17: 45952 | E17: Inversion | F17: =TEXT(D17,"mmmm yyyy") -> octubre 2025 | G17: =IF(B16<>"", B16, IF(C16<>"", -C16, "")) -> -513000 | H17: =IF(G17="", "", IF(G17>0, "Ingreso", "Gasto")) -> Gasto
A18: Papa transferencia | C18: =25000+62500 -> 87500 | D18: 45952 | E18: Inversion | F18: =TEXT(D18,"mmmm yyyy") -> octubre 2025 | G18: =IF(B17<>"", B17, IF(C17<>"", -C17, "")) -> -100000 | H18: =IF(G18="", "", IF(G18>0, "Ingreso", "Gasto")) -> Gasto
A19: Mochila Para Fumigar | C19: 190000 | D19: 45954 | E19: Inversion | F19: =TEXT(D19,"mmmm yyyy") -> octubre 2025 | G19: =IF(B18<>"", B18, IF(C18<>"", -C18, "")) -> -87500 | H19: =IF(G19="", "", IF(G19>0, "Ingreso", "Gasto")) -> Gasto
A20: Coadyudante Para fumigar | C20: 63000 | D20: 45954 | E20: Inversion | F20: =TEXT(D20,"mmmm yyyy") -> octubre 2025 | G20: =IF(B19<>"", B19, IF(C19<>"", -C19, "")) -> -190000 | H20: =IF(G20="", "", IF(G20>0, "Ingreso", "Gasto")) -> Gasto
A21: Papa transferencia | C21: 400000 | D21: 45955 | E21: Prestamo | F21: =TEXT(D21,"mmmm yyyy") -> octubre 2025 | G21: =IF(B20<>"", B20, IF(C20<>"", -C20, "")) -> -63000 | H21: =IF(G21="", "", IF(G21>0, "Ingreso", "Gasto")) -> Gasto
A22: Papa Efectivo Prestamo | C22: 400000 | D22: 45955 | E22: Prestamo | F22: =TEXT(D22,"mmmm yyyy") -> octubre 2025 | G22: =IF(B21<>"", B21, IF(C21<>"", -C21, "")) -> -400000 | H22: =IF(G22="", "", IF(G22>0, "Ingreso", "Gasto")) -> Gasto
A23: Jose Octubre 5 dias | C23: 125000 | D23: 45955 | E23: Inversion | F23: =TEXT(D23,"mmmm yyyy") -> octubre 2025 | G23: =IF(B22<>"", B22, IF(C22<>"", -C22, "")) -> -400000 | H23: =IF(G23="", "", IF(G23>0, "Ingreso", "Gasto")) -> Gasto
A24: Gastos Finde Semana | C24: 18000 | D24: 45957 | E24: Gastos | F24: =TEXT(D24,"mmmm yyyy") -> octubre 2025 | G24: =IF(B23<>"", B23, IF(C23<>"", -C23, "")) -> -125000 | H24: =IF(G24="", "", IF(G24>0, "Ingreso", "Gasto")) -> Gasto
A25: Luz Octubre | C25: 132669 | D25: 45958 | E25: Servicios | F25: =TEXT(D25,"mmmm yyyy") -> octubre 2025 | G25: =IF(B24<>"", B24, IF(C24<>"", -C24, "")) -> -18000 | H25: =IF(G25="", "", IF(G25>0, "Ingreso", "Gasto")) -> Gasto
A26: Papa Transferencia | C26: 400000 | D26: 45958 | E26: Prestamo | F26: =TEXT(D26,"mmmm yyyy") -> octubre 2025 | G26: =IF(B25<>"", B25, IF(C25<>"", -C25, "")) -> -132669 | H26: =IF(G26="", "", IF(G26>0, "Ingreso", "Gasto")) -> Gasto
A27: Marimar Motosierra | C27: 67000 | D27: 45958 | E27: Inversion | F27: =TEXT(D27,"mmmm yyyy") -> octubre 2025 | G27: =IF(B26<>"", B26, IF(C26<>"", -C26, "")) -> -400000 | H27: =IF(G27="", "", IF(G27>0, "Ingreso", "Gasto")) -> Gasto
A28: Transferencia a efectivo | C28: 60000 | D28: 45958 | E28: Gastos | F28: =TEXT(D28,"mmmm yyyy") -> octubre 2025 | G28: =IF(B27<>"", B27, IF(C27<>"", -C27, "")) -> -67000 | H28: =IF(G28="", "", IF(G28>0, "Ingreso", "Gasto")) -> Gasto
A29: Gastos Uber | C29: 20000 | D29: 45958 | E29: =IFERROR(__xludf.DUMMYFUNCTION("REGEXEXTRACT(A29,""[A-Za-z]+"")"),"Gastos") -> Gastos | F29: =TEXT(D29,"mmmm yyyy") -> octubre 2025 | G29: =IF(B28<>"", B28, IF(C28<>"", -C28, "")) -> -60000 | H29: =IF(G29="", "", IF(G29>0, "Ingreso", "Gasto")) -> Gasto
A30: Aplicacion Octubre | C30: 17000 | D30: 45961 | E30: =IFERROR(__xludf.DUMMYFUNCTION("REGEXEXTRACT(A30,""[A-Za-z]+"")"),"Aplicacion") -> Aplicacion | F30: =TEXT(D30,"mmmm yyyy") -> octubre 2025 | G30: =IF(B29<>"", B29, IF(C29<>"", -C29, "")) -> -20000 | H30: =IF(G30="", "", IF(G30>0, "Ingreso", "Gasto")) -> Gasto
A31: Sueldo Alexis Guantay Mercado Pago | C31: 200000 | D31: 45964 | E31: Alexis | F31: =TEXT(D31,"mmmm yyyy") -> noviembre 2025 | G31: =IF(B30<>"", B30, IF(C30<>"", -C30, "")) -> -17000 | H31: =IF(G31="", "", IF(G31>0, "Ingreso", "Gasto")) -> Gasto
A32: Netfilx Noviembre | C32: 11000 | D32: 45966 | E32: Servicios | F32: =TEXT(D32,"mmmm yyyy") -> noviembre 2025 | G32: =IF(B31<>"", B31, IF(C31<>"", -C31, "")) -> -200000 | H32: =IF(G32="", "", IF(G32>0, "Ingreso", "Gasto")) -> Gasto
A33: Servicios Internet Claro | C33: 20500 | D33: 45966 | E33: =IFERROR(__xludf.DUMMYFUNCTION("REGEXEXTRACT(A33,""[A-Za-z]+"")"),"Servicios") -> Servicios | F33: =TEXT(D33,"mmmm yyyy") -> noviembre 2025 | G33: =IF(B32<>"", B32, IF(C32<>"", -C32, "")) -> -11000 | H33: =IF(G33="", "", IF(G33>0, "Ingreso", "Gasto")) -> Gasto
A34: Tarjeta Octubre | C34: 98000 | D34: 45966 | E34: =IFERROR(__xludf.DUMMYFUNCTION("REGEXEXTRACT(A34,""[A-Za-z]+"")"),"Tarjeta") -> Tarjeta | F34: =TEXT(D34,"mmmm yyyy") -> noviembre 2025 | G34: =IF(B33<>"", B33, IF(C33<>"", -C33, "")) -> -20500 | H34: =IF(G34="", "", IF(G34>0, "Ingreso", "Gasto")) -> Gasto
A35: Rendimiento Frasco | B35: 66480 | D35: 45966 | E35: Frasco | F35: =TEXT(D35,"mmmm yyyy") -> noviembre 2025 | G35: =IF(B34<>"", B34, IF(C34<>"", -C34, "")) -> -98000 | H35: =IF(G35="", "", IF(G35>0, "Ingreso", "Gasto")) -> Gasto
A36: Raul Octubre 14 dias | C36: 350000 | D36: 45966 | E36: Inversion | F36: =TEXT(D36,"mmmm yyyy") -> noviembre 2025 | G36: =IF(B35<>"", B35, IF(C35<>"", -C35, "")) -> 66480 | H36: =IF(G36="", "", IF(G36>0, "Ingreso", "Gasto")) -> Ingreso
A37: Sueldo Octubre Santa Clara | B37: 2070000 | D37: 45968 | E37: =IFERROR(__xludf.DUMMYFUNCTION("REGEXEXTRACT(A37,""[A-Za-z]+"")"),"Sueldo") -> Sueldo | F37: =TEXT(D37,"mmmm yyyy") -> noviembre 2025 | G37: =IF(B36<>"", B36, IF(C36<>"", -C36, "")) -> -350000 | H37: =IF(G37="", "", IF(G37>0, "Ingreso", "Gasto")) -> Gasto
A38: Uber Finde Efectivo | B38: 24000 | D38: 45969 | E38: =IFERROR(__xludf.DUMMYFUNCTION("REGEXEXTRACT(A38,""[A-Za-z]+"")"),"Uber") -> Uber | F38: =TEXT(D38,"mmmm yyyy") -> noviembre 2025 | G38: =IF(B37<>"", B37, IF(C37<>"", -C37, "")) -> 2070000 | H38: =IF(G38="", "", IF(G38>0, "Ingreso", "Gasto")) -> Ingreso
A39: Uber Transferencia | B39: 15000 | D39: 45970 | E39: =IFERROR(__xludf.DUMMYFUNCTION("REGEXEXTRACT(A39,""[A-Za-z]+"")"),"Uber") -> Uber | F39: =TEXT(D39,"mmmm yyyy") -> noviembre 2025 | G39: =IF(B38<>"", B38, IF(C38<>"", -C38, "")) -> 24000 | H39: =IF(G39="", "", IF(G39>0, "Ingreso", "Gasto")) -> Ingreso
A40: Devolucion Marimar Prestamos | C40: 30000 | D40: 45971 | E40: Gastos | F40: =TEXT(D40,"mmmm yyyy") -> noviembre 2025 | G40: =IF(B39<>"", B39, IF(C39<>"", -C39, "")) -> 15000 | H40: =IF(G40="", "", IF(G40>0, "Ingreso", "Gasto")) -> Ingreso
A41: Sandwiches | C41: 13500 | D41: 45971 | E41: Gastos | F41: =TEXT(D41,"mmmm yyyy") -> noviembre 2025 | G41: =IF(B40<>"", B40, IF(C40<>"", -C40, "")) -> -30000 | H41: =IF(G41="", "", IF(G41>0, "Ingreso", "Gasto")) -> Gasto
...
